Workbook

Sheet 0_CAPA
C4: CRONOANÁLISE INDUSTRIAL
C5: Diagnóstico de capacidade, produtividade e tempo-padrão
D10: IMPAKTTO
C11: ELABORADOR POR | D11: Alexandre Souza
C12: INÍCIO | D12: 2026-05-09
C13: ESCOPO | D13: Fábrica completa — usinagem CNC
C14: MÉTODO | D14: Apontamento histórico (OCR) + Cronometragem + Amostragem do Trabalho
C15: ENTREGÁVEIS | D15: Tempo-Padrão · Carga-Máquina · Produtividade O×M×P · Plano de Melhoria
C19: SUMÁRIO
C21: 1 | D21: DASHBOARD | E21: Visão executiva — KPIs, Pareto de paradas, ocupação
C22: 2 | D22: INSTRUÇÕES | E22: Guia de uso e fluxo metodológico
C23: 3 | D23: CADASTROS | E23: Máquinas, operadores, peças, códigos parada, turnos
C24: 4 | D24: APONTAMENTO_HIST | E24: Histórico do formulário IMPAKTTO (via OCR)
C25: 5 | D25: COLETA_CRONO | E25: Cronometragem de calibração (10 ciclos × peça)
C26: 6 | D26: COLETA_AMOSTRAGEM | E26: Amostragem do trabalho (work sampling)
C27: 7 | D27: TEMPOS_PADRAO | E27: TP oficial — Fator de Apontamento × peças/hora
C28: 8 | D28: CARGA_MAQUINA | E28: Capacidade × demanda × ocupação real
C29: 9 | D29: PRODUTIVIDADE | E29: Matriz Operador × Máquina × Peça
C30: 10 | D30: PLANO_MELHORIA | E30: Ações priorizadas (impacto × esforço)

Sheet 1_DASHBOARD
B2: DASHBOARD EXECUTIVO
B3: IMPAKTTO · Cronoanálise · atualização automática conforme dados são preenchidos
B7: OPs REGISTRADAS | D7: QTD PRODUZIDA | F7: % ATENDIDO | H7: PARADAS REGISTRADAS
B8: =IFERROR(_AGREG!B2,"—") | D8: =IFERROR(_AGREG!B3,"—") | F8: =IFERROR(_AGREG!B4,"—") | H8: =IFERROR(_AGREG!B5,"—")
B10: no apontamento OCR | D10: soma das peças | F10: produzido ÷ pedido | H10: ocorrências códigos P
B14: PRODUTIVIDADE POR OPERADOR | G14: PRODUTIVIDADE POR PEÇA
B15: OPs · Quantidade produzida · % do mix de produção | G15: Mix produzido — base item do formulário
B17: OPERADOR | C17: OPs | D17: QTD_PROD | E17: % MIX | G17: ITEM | H17: QTD_PROD | I17: % MIX
B18: =IFERROR(_AGREG!D3,"") | C18: =IFERROR(_AGREG!E3,"") | D18: =IFERROR(_AGREG!F3,"") | E18: =IFERROR(_AGREG!G3,"") | G18: =IFERROR(_AGREG!K3,"") | H18: =IFERROR(_AGREG!M3,"") | I18: =IFERROR(_AGREG!N3,"")
B19: =IFERROR(_AGREG!D4,"") | C19: =IFERROR(_AGREG!E4,"") | D19: =IFERROR(_AGREG!F4,"") | E19: =IFERROR(_AGREG!G4,"") | G19: =IFERROR(_AGREG!K4,"") | H19: =IFERROR(_AGREG!M4,"") | I19: =IFERROR(_AGREG!N4,"")
B20: =IFERROR(_AGREG!D5,"") | C20: =IFERROR(_AGREG!E5,"") | D20: =IFERROR(_AGREG!F5,"") | E20: =IFERROR(_AGREG!G5,"") | G20: =IFERROR(_AGREG!K5,"") | H20: =IFERROR(_AGREG!M5,"") | I20: =IFERROR(_AGREG!N5,"")
B21: =IFERROR(_AGREG!D6,"") | C21: =IFERROR(_AGREG!E6,"") | D21: =IFERROR(_AGREG!F6,"") | E21: =IFERROR(_AGREG!G6,"") | G21: =IFERROR(_AGREG!K6,"") | H21: =IFERROR(_AGREG!M6,"") | I21: =IFERROR(_AGREG!N6,"")
B22: =IFERROR(_AGREG!D7,"") | C22: =IFERROR(_AGREG!E7,"") | D22: =IFERROR(_AGREG!F7,"") | E22: =IFERROR(_AGREG!G7,"")
B45: PARETO DE PARADAS (frequência)
B46: Códigos vistos no formulário — frequência (não horas, ainda)
B48: CÓDIGO | C48: OCORRÊNCIAS | D48: % ACUM
B49: =IFERROR(_AGREG!P3,"") | C49: =IFERROR(_AGREG!Q3,"") | D49: =IFERROR(_AGREG!R3,"")
B50: =IFERROR(_AGREG!P4,"") | C50: =IFERROR(_AGREG!Q4,"") | D50: =IFERROR(_AGREG!R4,"")
B51: =IFERROR(_AGREG!P5,"") | C51: =IFERROR(_AGREG!Q5,"") | D51: =IFERROR(_AGREG!R5,"")
B52: =IFERROR(_AGREG!P6,"") | C52: =IFERROR(_AGREG!Q6,"") | D52: =IFERROR(_AGREG!R6,"")

Sheet _AGREG
A1: KPIs (dinâmico) | D1: PRODUTIVIDADE — POR OPERADOR | K1: PRODUTIVIDADE — POR PEÇA | P1: Pareto Paradas (frequência)
A2: OPs registradas | B2: =COUNTA('4_APONTAMENTO_HIST'!$A$4:$A$203) | D2: OPERADOR | E2: OPs | F2: QTD_PROD | G2: % MIX | I2: =SUM('4_APONTAMENTO_HIST'!$G$4:$G$203) | K2: ITEM | L2: OPs | M2: QTD_PROD | N2: % MIX | P2: CÓDIGO | Q2: OCORR | R2: % ACUM
A3: Total qtd produzida | B3: =SUM('4_APONTAMENTO_HIST'!$G$4:$G$203) | D3: Clayton | E3: =COUNTIF('4_APONTAMENTO_HIST'!$O$4:$O$203,"*Clayton*") | F3: =SUMIF('4_APONTAMENTO_HIST'!$O$4:$O$203,"*Clayton*",'4_APONTAMENTO_HIST'!$G$4:$G$203) | G3: =IFERROR(F3/MAX($I$2,1),0) | K3: 30809 | L3: =COUNTIF('4_APONTAMENTO_HIST'!$C$4:$C$203,30809) | M3: =SUMIF('4_APONTAMENTO_HIST'!$C$4:$C$203,30809,'4_APONTAMENTO_HIST'!$G$4:$G$203) | N3: =IFERROR(M3/MAX($I$2,1),0) | P3: P01 | Q3: =COUNTIF('4_APONTAMENTO_HIST'!$M$4:$M$203,"P01") | R3: =IFERROR(SUM($Q$3:Q3)/SUM($Q$3:$Q$10),0)
A4: % atendido (prod/ped) | B4: =IFERROR(SUM('4_APONTAMENTO_HIST'!$G$4:$G$203)/SUM('4_APONTAMENTO_HIST'!$H$4:$H$203),0) | D4: Ulton | E4: =COUNTIF('4_APONTAMENTO_HIST'!$O$4:$O$203,"*Ulton*") | F4: =SUMIF('4_APONTAMENTO_HIST'!$O$4:$O$203,"*Ulton*",'4_APONTAMENTO_HIST'!$G$4:$G$203) | G4: =IFERROR(F4/MAX($I$2,1),0) | K4: 31552 | L4: =COUNTIF('4_APONTAMENTO_HIST'!$C$4:$C$203,31552) | M4: =SUMIF('4_APONTAMENTO_HIST'!$C$4:$C$203,31552,'4_APONTAMENTO_HIST'!$G$4:$G$203) | N4: =IFERROR(M4/MAX($I$2,1),0) | P4: P07 | Q4: =COUNTIF('4_APONTAMENTO_HIST'!$M$4:$M$203,"P07") | R4: =IFERROR(SUM($Q$3:Q4)/SUM($Q$3:$Q$10),0)
A5: Paradas registradas | B5: =SUMPRODUCT(--('4_APONTAMENTO_HIST'!$M$4:$M$203<>"")) | D5: Vanildo | E5: =COUNTIF('4_APONTAMENTO_HIST'!$O$4:$O$203,"*Vanildo*") | F5: =SUMIF('4_APONTAMENTO_HIST'!$O$4:$O$203,"*Vanildo*",'4_APONTAMENTO_HIST'!$G$4:$G$203) | G5: =IFERROR(F5/MAX($I$2,1),0) | K5: 31652 | L5: =COUNTIF('4_APONTAMENTO_HIST'!$C$4:$C$203,31652) | M5: =SUMIF('4_APONTAMENTO_HIST'!$C$4:$C$203,31652,'4_APONTAMENTO_HIST'!$G$4:$G$203) | N5: =IFERROR(M5/MAX($I$2,1),0) | P5: P11 | Q5: =COUNTIF('4_APONTAMENTO_HIST'!$M$4:$M$203,"P11") | R5: =IFERROR(SUM($Q$3:Q5)/SUM($Q$3:$Q$10),0)
D6: Vita | E6: =COUNTIF('4_APONTAMENTO_HIST'!$O$4:$O$203,"*Vita*") | F6: =SUMIF('4_APONTAMENTO_HIST'!$O$4:$O$203,"*Vita*",'4_APONTAMENTO_HIST'!$G$4:$G$203) | G6: =IFERROR(F6/MAX($I$2,1),0) | K6: 31553 | L6: =COUNTIF('4_APONTAMENTO_HIST'!$C$4:$C$203,31553) | M6: =SUMIF('4_APONTAMENTO_HIST'!$C$4:$C$203,31553,'4_APONTAMENTO_HIST'!$G$4:$G$203) | N6: =IFERROR(M6/MAX($I$2,1),0) | P6: P16 | Q6: =COUNTIF('4_APONTAMENTO_HIST'!$M$4:$M$203,"P16") | R6: =IFERROR(SUM($Q$3:Q6)/SUM($Q$3:$Q$10),0)
D7: dilma | E7: =COUNTIF('4_APONTAMENTO_HIST'!$O$4:$O$203,"*dilma*") | F7: =SUMIF('4_APONTAMENTO_HIST'!$O$4:$O$203,"*dilma*",'4_APONTAMENTO_HIST'!$G$4:$G$203) | G7: =IFERROR(F7/MAX($I$2,1),0)
A15: ℹ Tudo calculado de 4_APONTAMENTO_HIST. Atualiza com novas fotos.

Sheet 2_INSTRUCOES
B2: INSTRUÇÕES E FLUXO
B6: OBJETIVO | C6: Cronoanálise IMPAKTTO → Tempo-Padrão, Carga-Máquina, Produtividade O×M×P, Plano de Melhoria.
B7: FONTE PRIMÁRIA | C7: Apontamento manual existente (formulário IMPAKTTO) → digitalizado via OCR Claude Vision na aba 4_APONTAMENTO_HIST.
B8: FONTES SECUNDÁRIAS | C8: 5_COLETA_CRONO (cronometragem de calibração) e 6_COLETA_AMOSTRAGEM (work sampling).
B10: FLUXO METODOLÓGICO
B12: 1 | C12: Preencher 3_CADASTROS (máquinas, operadores, peças, códigos parada, turnos).
B13: 2 | C13: Importar histórico do formulário IMPAKTTO via OCR → 4_APONTAMENTO_HIST (60 dias).
B14: 3 | C14: Cronometrar peças Pareto (5–8 peças, 10 ciclos cada) → 5_COLETA_CRONO.
B15: 4 | C15: Amostragem do trabalho (~400 obs/máquina) → 6_COLETA_AMOSTRAGEM.
B16: 5 | C16: TP gerado em 7_TEMPOS_PADRAO consolida 5 + valida com 4.
B17: 6 | C17: 8_CARGA_MAQUINA: capacidade × demanda × ocupação real.
B18: 7 | C18: 9_PRODUTIVIDADE: matriz Operador × Máquina × Peça + Fator de Apontamento.
B19: 8 | C19: 1_DASHBOARD atualiza automaticamente; revisar e validar com cliente.
B20: 9 | C20: 10_PLANO_MELHORIA: priorizar ações por impacto/esforço.
B23: REGRAS
B24: • | C24: Tempos sempre em MINUTOS decimais (7,5 = 7 min 30 s).
B25: • | C25: Datas DD/MM/AAAA.
B26: • | C26: Códigos de parada padronizados pela aba 3 (lista P01..Pxx).
B27: • | C27: Coluna AUDIT em 4 obrigatória antes de entrar em análise (OK / AJ / ??).
B28: • | C28: Auditoria amostral 10% das linhas digitalizadas.
B29: • | C29: Nunca apagar cadastro com vínculo ativo — usar coluna ATIVO=N.

Sheet 3_CADASTROS
A1: CADASTROS
A4: MÁQUINAS
A5: COD_MAQ | B5: NOME | C5: TIPO | D5: CÉLULA | E5: EIXOS | F5: HORAS_DIA | G5: TURNOS | H5: ATIVO
A20: OPERADORES
A21: COD_OP | B21: NOME | C21: FUNÇÃO | D21: TURNO | E21: ADMISSÃO | F21: MAQ_PRIM | G21: ATIVO | H21: OBS
A42: PEÇAS
A43: COD_PECA | B43: DESCRIÇÃO | C43: CLIENTE | D43: MATERIAL | E43: PESO_KG | F43: MAQ_PRINC | G43: N_PROG | H43: ATIVO
A71: CÓDIGOS DE PARADA
A72: CÓDIGO | B72: DESCRIÇÃO | C72: CATEGORIA | D72: EVITÁVEL | E72: RESPONSÁVEL | F72: OBS
A73: P01 | B73: (confirmar com IMPAKTTO) | C73: ? | D73: ? | E73: ?
A74: P07 | B74: (confirmar com IMPAKTTO) | C74: ? | D74: ? | E74: ?
A75: P11 | B75: (confirmar com IMPAKTTO) | C75: ? | D75: ? | E75: ?
A76: P16 | B76: (confirmar com IMPAKTTO) | C76: ? | D76: ? | E76: ?
A90: TURNOS
A91: TURNO | B91: INÍCIO | C91: FIM | D91: INTERVALO_MIN | E91: DIAS | F91: HORAS_LIQ

Sheet 4_APONTAMENTO_HIST
A1: APONTAMENTO HISTÓRICO (OCR formulário IMPAKTTO)
A3: DATA | B3: CLIENTE | C3: ID_OP | D3: ITEM | E3: DESCRICAO_OP | F3: N_PROG | G3: QTD_PROD | H3: QTD_PED | I3: H_INICIO | J3: H_FIM | K3: TOTAL_MIN | L3: NC | M3: COD_PARADA | N3: T_PARADA_MIN | O3: OPERADOR | P3: MAQUINA | Q3: AUDIT
A4: 06/04/2026 | B4: MATÃO | C4: 30809 | D4: 2,2 | E4: Avanco e face [???] | F4: 249 | G4: 37 | H4: 220 | I4: 08:00 | J4: 17:30 | K4: ??? | L4: 00:02 | M4: P07 | N4: ??? | O4: Wendell [???] | P4: ???
A5: 06/04/2026 | B5: MATÃO | C5: 30809 | D5: 2,2 | E5: [em branco] | F5: 249 | G5: 97 | H5: 220 | I5: 20:00 | J5: 02:30 | K5: ??? | L5: 00:00 | M5: P07 | N5: ??? | O5: ??? | P5: ???
A6: 07/04/2026 | B6: MATÃO | C6: 30809 | D6: 2,2 | E6: [em branco] | F6: 249 | G6: 50 | H6: 220 | I6: 07:30 | J6: 20:00 | K6: 720 | L6: 01:00 | M6: P07 | N6: ??? | O6: Clayton | P6: Torno com acionada
A7: 07/04/2026 | B7: MATÃO | C7: 31552 | D7: 2,2 | E7: Furacao e chaveta | F7: 249 | G7: 23 | H7: 220 | I7: 20:00 | J7: 02:30 | K7: 390 | L7: ??? | M7: P11 | N7: ??? | O7: ??? | P7: ???
A8: 08/04/2026 | B8: MATÃO | C8: 31552 | D8: 2,2 | E8: [em branco] | F8: 249 | G8: 23 | H8: 150 | I8: 02:30 | J8: 07:50 | K8: 320 | L8: ??? | M8: ??? | N8: ??? | O8: ??? | P8: ???
A9: 08/04/2026 | B9: MATÃO | C9: 31552 | D9: 2,2 | E9: Furacao e chaveta | F9: 249 | G9: 14 | H9: 150 | I9: 07:50 | J9: 11:40 | K9: 230 | L9: ??? | M9: P01 | N9: ??? | O9: Wendell [???] | P9: Centro
A10: 08/04/2026 | B10: MATÃO | C10: 31552 | D10: 2,2 | E10: Furacao e chaveta | F10: 249 | G10: 10 | H10: 150 | I10: 17:40 | J10: 16:20 | K10: ??? | L10: ??? | M10: P01 | N10: ??? | O10: Clayton | P10: Torno com acionada
A11: 09/04/2026 | B11: MATÃO | C11: 31552 | D11: 2,2 | E11: Furacao e chaveta | F11: 249 | G11: 9 | H11: 150 | I11: 17:15 | J11: 19:30 | K11: 135 | L11: ??? | M11: ??? | N11: ??? | O11: Wendell [???] | P11: Centro
A12: 09/04/2026 | B12: MATÃO | C12: 31552 | D12: 2,2 | E12: Furacao e chaveta | F12: 249 | G12: 44 | H12: 150 | I12: 08:00 | J12: 19:30 | K12: 690 | L12: ??? | M12: P07 | N12: ??? | O12: Clayton | P12: Torno com acionada
A13: 09/04/2026 | B13: MATÃO | C13: 31652 | D13: 2,3 | E13: Furacao e Chaveta | F13: 249 | G13: 5 | H13: 150 | I13: 08:00 | J13: 19:30 | K13: 690 | L13: ??? | M13: P16 | N13: ??? | O13: ??? | P13: ???
A14: 10/04/2026 | B14: MATÃO | C14: 31552 | D14: 1,2 | E14: Furacao e Chaveta | F14: 249 | G14: 30 | H14: 150 | I14: 23:00 | J14: 07:00 | K14: 480 | L14: ??? | M14: P07 | N14: ??? | O14: Vanildo | P14: Centro
A15: 10/04/2026 | B15: MATÃO | C15: 31552 | D15: 1,2 | E15: Furacao e chaveta | F15: 175 | G15: 24 | H15: 100 | I15: 09:30 | J15: 16:20 | K15: 410 | L15: ??? | M15: 87 [???] | N15: ??? | O15: Danilo [???] | P15: Centro
A16: 11/04/2026 | B16: MATÃO | C16: 31552 | D16: 1,2 | E16: Furacao e Chaveta | F16: 175 | G16: 16 | H16: 100 | I16: 20:30 | J16: 04:40 | K16: 490 | L16: ??? | M16: P07 | N16: ??? | O16: Vita [???] | P16: Centro
A17: 13/04/2026 | B17: MATÃO | C17: 31552 | D17: 1,4 | E17: Furacao e chaveta | F17: 175 | G17: 23 | H17: 100 | I17: 07:30 | J17: ??? | K17: ??? | L17: ??? | M17: ??? | N17: ??? | O17: Clayton | P17: Torno com acionada
A18: 15/04/2026 | B18: rod | C18: teste | D18: ??? | E18: Furacao e chaveta | F18: 175 | G18: 37 | H18: 100 | I18: 07:40 | J18: 19:00 | K18: 680 | L18: ??? | M18: P07 | N18: ??? | O18: Clayton | P18: Torno com acionada
A19: 15/04/2026 | B19: MATÃO | C19: 31553 | D19: 1,1 | E19: Furacao e chaveta | F19: 525 | G19: 5 | H19: 5 | I19: 08:30 | J19: 11:40 | K19: 190 | L19: ??? | M19: ??? | N19: ??? | O19: Wendell [???] | P19: ???
A20: 15/04/2026 | B20: MATÃO | C20: 31553 | D20: 1,2 | E20: Furacao e Chaveta | F20: 175 | G20: 19 | H20: 80 | I20: 11:45 | J20: 17:30 | K20: 345 | L20: ??? | M20: P07 | N20: ??? | O20: Clayton | P20: Torno com acionada
A21: 15/04/2026 | B21: MATÃO | C21: 31553 | D21: 1,2 | E21: Furacao e Chaveta | F21: 175 | G21: 31 | H21: 80 | I21: 20:15 | J21: 06:00 | K21: 585 | L21: ??? | M21: P07 | N21: ??? | O21: Vanildo | P21: ???
A22: 18/04/2026 | B22: matro | C22: 31553 | D22: 1,4 | F22: 125 | G22: 80 | H22: 30 | I22: 07:30 | J22: 15:35 | M22: P07 | O22: Clayton | P22: LO-40 | Q22: CCF13052026_p1
A23: 18/04/2026 | B23: matro | C23: 31553 | D23: 1,4 | F23: 494 | G23: 141 | H23: 141 | O23: Clayton | P23: LO-40 | Q23: CCF13052026_p1
A24: 18/04/2026 | B24: matro | C24: 31553 | D24: 1,4 | F24: 94 | G24: 16 | H24: 16 | O24: Clayton | P24: LO-40 | Q24: CCF13052026_p1
A25: 18/04/2026 | B25: matro | C25: 32414 | D25: 1 | F25: 110 | G25: 10 | H25: 10 | O25: Clayton | P25: LO-40 | Q25: CCF13052026_p1
A26: 30/04/2026 | B26: vimin | C26: 31698 | D26: 1 | F26: 276 | G26: 19 | H26: 54 | O26: Clayton | P26: LO-40 | Q26: CCF13052026_p2
A27: 30/04/2026 | B27: vimin | C27: 31699 | D27: 1 | F27: 437 | G27: 57 | O27: Clayton | P27: LO-40 | Q27: CCF13052026_p2
A28: 12/05/2026 | B28: vimin | C28: 31468 | D28: 2 | F28: 947 | G28: 63 | O28: Clayton | P28: LO-40 | Q28: CCF13052026_p2
A29: 13/05/2026 | B29: vimin | C29: 31486 | D29: 2 | F29: 947 | G29: 84 | O29: Clayton | P29: LO-40 | Q29: CCF13052026_p2
A30: 08/04/2026 | C30: 30838 | E30: Furo loblonga | G30: 665 | I30: 08:30 | J30: 15:35 | M30: P03 | O30: Wendell | P30: Centro Usinagem | Q30: WA14052026_p1
A31: 09/04/2026 | C31: 30838 | E31: Furo loblonga | G31: 305 | I31: 10:00 | O31: Andrei | P31: Centro Usinagem | Q31: WA14052026_p1
A32: 06/04/2026 | C32: 30838 | I32: 09:35 | J32: 12:40 | M32: P12 | P32: Centro Usinagem | Q32: WA14052026_p1
A33: 07/04/2026 | C33: 30838 | I33: 08:30 | J33: 09:00 | M33: P15 | P33: Centro Usinagem | Q33: WA14052026_p1
A34: 01/04/2026 | B34: matro | C34: 31553 | D34: 1,4 | F34: 1 | G34: 182 | O34: Wendell | P34: Centro Usinagem | Q34: WA14052026_p2
A35: 08/04/2026 | B35: matro | D35: 1 | M35: P07 | O35: Wendell | P35: Centro Usinagem | Q35: WA14052026_p2
A36: 15/04/2026 | B36: matro | C36: 31553 | D36: 1,4 | O36: Wendell | P36: Centro Usinagem | Q36: WA14052026_p2
A37: 18/04/2026 | B37: matro | C37: 31553 | D37: 4 | E37: 2a CNC c/Furo | F37: 1 | G37: 80 | M37: P01 | O37: Wendell | P37: Centro Usinagem | Q37: WA14052026_p3
A38: 18/04/2026 | B38: matro | C38: 31553 | D38: 4 | F38: 494 | G38: 141 | H38: 141 | O38: Wendell | P38: Centro Usinagem | Q38: WA14052026_p3
A39: 23/04/2026 | B39: matro | C39: 31553 | D39: 4 | M39: P07 | O39: Wendell | P39: Centro Usinagem | Q39: WA14052026_p3
A40: 23/04/2026 | B40: matro | C40: 31553 | D40: 4 | O40: Wendell | P40: Centro Usinagem | Q40: WA14052026_p3
A41: 06/05/2026 | B41: matro | D41: 4 | O41: Wendell | P41: Centro Usinagem | Q41: WA14052026_p3
...

Sheet 5_COLETA_CRONO
A1: CRONOMETRAGEM DE CALIBRAÇÃO
A2: 10 ciclos por peça Pareto · ritmo Westinghouse · tolerâncias 13% padrão
A4: DATA | B4: MÁQUINA | C4: PEÇA | D4: OPERADOR | E4: OBSERVADOR | F4: CICLO | G4: T_CICLO_MIN | H4: RITMO | I4: FATOR_TOL | J4: TN_MIN | K4: TP_MIN | L4: SETUP_MIN | M4: QTD_LOTE | N4: TT_LOTE_MIN | O4: OBS
J5: =IFERROR(G5*H5,"") | K5: =IFERROR(J5*(1+I5),"") | N5: =IFERROR(L5+K5*M5,"")
J6: =IFERROR(G6*H6,"") | K6: =IFERROR(J6*(1+I6),"") | N6: =IFERROR(L6+K6*M6,"")
J7: =IFERROR(G7*H7,"") | K7: =IFERROR(J7*(1+I7),"") | N7: =IFERROR(L7+K7*M7,"")
J8: =IFERROR(G8*H8,"") | K8: =IFERROR(J8*(1+I8),"") | N8: =IFERROR(L8+K8*M8,"")
J9: =IFERROR(G9*H9,"") | K9: =IFERROR(J9*(1+I9),"") | N9: =IFERROR(L9+K9*M9,"")
J10: =IFERROR(G10*H10,"") | K10: =IFERROR(J10*(1+I10),"") | N10: =IFERROR(L10+K10*M10,"")
J11: =IFERROR(G11*H11,"") | K11: =IFERROR(J11*(1+I11),"") | N11: =IFERROR(L11+K11*M11,"")
J12: =IFERROR(G12*H12,"") | K12: =IFERROR(J12*(1+I12),"") | N12: =IFERROR(L12+K12*M12,"")
J13: =IFERROR(G13*H13,"") | K13: =IFERROR(J13*(1+I13),"") | N13: =IFERROR(L13+K13*M13,"")
J14: =IFERROR(G14*H14,"") | K14: =IFERROR(J14*(1+I14),"") | N14: =IFERROR(L14+K14*M14,"")
J15: =IFERROR(G15*H15,"") | K15: =IFERROR(J15*(1+I15),"") | N15: =IFERROR(L15+K15*M15,"")
J16: =IFERROR(G16*H16,"") | K16: =IFERROR(J16*(1+I16),"") | N16: =IFERROR(L16+K16*M16,"")
... J154: =IFERROR(G154*H154,"") | K154: =IFERROR(J154*(1+I154),"") | N154: =IFERROR(L154+K154*M154,"")

Sheet 6_COLETA_AMOSTRAGEM
A1: AMOSTRAGEM DO TRABALHO
A2: ~400 observações por máquina · IC 95% · erro 5%
A4: DATA | B4: ROUND | C4: HORA | D4: MÁQUINA | E4: STATUS | F4: COD_PARADA | G4: NOTA

Sheet 7_TEMPOS_PADRAO
A1: TEMPOS-PADRÃO OFICIAIS
A2: TP Crono × Tempo Apontado → Fator de Apontamento (FA)
A4: COD_PECA | B4: DESCRIÇÃO | C4: MÁQUINA | D4: TP_CRONO_MIN | E4: T_MED_APONT_MIN | F4: FA | G4: TP_OFICIAL_MIN | H4: SETUP_MIN | I4: PCS/HORA | J4: OBS
F5: =IFERROR(E5/D5,"") | I5: =IFERROR(60/G5,"")
F6: =IFERROR(E6/D6,"") | I6: =IFERROR(60/G6,"")
F7: =IFERROR(E7/D7,"") | I7: =IFERROR(60/G7,"")
F8: =IFERROR(E8/D8,"") | I8: =IFERROR(60/G8,"")
F9: =IFERROR(E9/D9,"") | I9: =IFERROR(60/G9,"")
F10: =IFERROR(E10/D10,"") | I10: =IFERROR(60/G10,"")
F11: =IFERROR(E11/D11,"") | I11: =IFERROR(60/G11,"")
F12: =IFERROR(E12/D12,"") | I12: =IFERROR(60/G12,"")
F13: =IFERROR(E13/D13,"") | I13: =IFERROR(60/G13,"")
F14: =IFERROR(E14/D14,"") | I14: =IFERROR(60/G14,"")
F15: =IFERROR(E15/D15,"") | I15: =IFERROR(60/G15,"")
F16: =IFERROR(E16/D16,"") | I16: =IFERROR(60/G16,"")
... F54: =IFERROR(E54/D54,"") | I54: =IFERROR(60/G54,"")

Sheet 8_CARGA_MAQUINA
A1: CARGA-MÁQUINA
A2: Capacidade teórica × demanda real × ocupação · barra de cor por máquina
A4: MÁQUINA | B4: DIAS_MES | C4: H_DIA | D4: CAP_TEÓRICA_H | E4: H_PRODUZIDA | F4: H_SETUP | G4: H_PARADA | H4: OCUPAÇÃO_% | I4: OBS
D5: =IFERROR(B5*C5,"") | H5: =IFERROR((E5+F5)/D5,"")
D6: =IFERROR(B6*C6,"") | H6: =IFERROR((E6+F6)/D6,"")
D7: =IFERROR(B7*C7,"") | H7: =IFERROR((E7+F7)/D7,"")
D8: =IFERROR(B8*C8,"") | H8: =IFERROR((E8+F8)/D8,"")
D9: =IFERROR(B9*C9,"") | H9: =IFERROR((E9+F9)/D9,"")
D10: =IFERROR(B10*C10,"") | H10: =IFERROR((E10+F10)/D10,"")
D11: =IFERROR(B11*C11,"") | H11: =IFERROR((E11+F11)/D11,"")
D12: =IFERROR(B12*C12,"") | H12: =IFERROR((E12+F12)/D12,"")
D13: =IFERROR(B13*C13,"") | H13: =IFERROR((E13+F13)/D13,"")
D14: =IFERROR(B14*C14,"") | H14: =IFERROR((E14+F14)/D14,"")
D15: =IFERROR(B15*C15,"") | H15: =IFERROR((E15+F15)/D15,"")
D16: =IFERROR(B16*C16,"") | H16: =IFERROR((E16+F16)/D16,"")
... D24: =IFERROR(B24*C24,"") | H24: =IFERROR((E24+F24)/D24,"")

Sheet 9_PRODUTIVIDADE
A1: PRODUTIVIDADE — MATRIZ O × M × P
A2: Eficiência = (QTD × TP_OFICIAL) ÷ T_REAL · heatmap por linha
A4: OPERADOR | B4: MÁQUINA | C4: PEÇA | D4: QTD_PROD | E4: TP_OFICIAL_MIN | F4: T_REAL_MIN | G4: EFICIÊNCIA | H4: FA_LOCAL | I4: OBS
G5: =IFERROR(D5*E5/F5,"") | H5: =IFERROR(F5/(D5*E5),"")
G6: =IFERROR(D6*E6/F6,"") | H6: =IFERROR(F6/(D6*E6),"")
G7: =IFERROR(D7*E7/F7,"") | H7: =IFERROR(F7/(D7*E7),"")
G8: =IFERROR(D8*E8/F8,"") | H8: =IFERROR(F8/(D8*E8),"")
G9: =IFERROR(D9*E9/F9,"") | H9: =IFERROR(F9/(D9*E9),"")
G10: =IFERROR(D10*E10/F10,"") | H10: =IFERROR(F10/(D10*E10),"")
G11: =IFERROR(D11*E11/F11,"") | H11: =IFERROR(F11/(D11*E11),"")
G12: =IFERROR(D12*E12/F12,"") | H12: =IFERROR(F12/(D12*E12),"")
G13: =IFERROR(D13*E13/F13,"") | H13: =IFERROR(F13/(D13*E13),"")
G14: =IFERROR(D14*E14/F14,"") | H14: =IFERROR(F14/(D14*E14),"")
G15: =IFERROR(D15*E15/F15,"") | H15: =IFERROR(F15/(D15*E15),"")
G16: =IFERROR(D16*E16/F16,"") | H16: =IFERROR(F16/(D16*E16),"")
... G104: =IFERROR(D104*E104/F104,"") | H104: =IFERROR(F104/(D104*E104),"")

Sheet 10_PLANO_MELHORIA
A1: PLANO DE MELHORIA
A2: Ações priorizadas: PRIORIDADE = IMPACTO ÷ ESFORÇO (1–5 cada)
A4: ID | B4: AÇÃO | C4: ÁREA | D4: IMPACTO | E4: ESFORÇO | F4: PRIORIDADE | G4: RESPONSÁVEL | H4: PRAZO | I4: STATUS
A5: =IF(B5<>"",ROW()-4,"") | F5: =IFERROR(D5/E5,"")
A6: =IF(B6<>"",ROW()-4,"") | F6: =IFERROR(D6/E6,"")
A7: =IF(B7<>"",ROW()-4,"") | F7: =IFERROR(D7/E7,"")
A8: =IF(B8<>"",ROW()-4,"") | F8: =IFERROR(D8/E8,"")
A9: =IF(B9<>"",ROW()-4,"") | F9: =IFERROR(D9/E9,"")
A10: =IF(B10<>"",ROW()-4,"") | F10: =IFERROR(D10/E10,"")
A11: =IF(B11<>"",ROW()-4,"") | F11: =IFERROR(D11/E11,"")
A12: =IF(B12<>"",ROW()-4,"") | F12: =IFERROR(D12/E12,"")
A13: =IF(B13<>"",ROW()-4,"") | F13: =IFERROR(D13/E13,"")
A14: =IF(B14<>"",ROW()-4,"") | F14: =IFERROR(D14/E14,"")
A15: =IF(B15<>"",ROW()-4,"") | F15: =IFERROR(D15/E15,"")
A16: =IF(B16<>"",ROW()-4,"") | F16: =IFERROR(D16/E16,"")
... A34: =IF(B34<>"",ROW()-4,"") | F34: =IFERROR(D34/E34,"")
